Workbook

Sheet Folder pagecounts and compariso
A1: Folder | B1: Approx date | C1: Notes | D1: PW notes | E1: PJ/JL date | F1: Earliest date | G1: latest date | H1: PW page count | I1: Zebrapedia page count | J1: PDF page count | K1: Zebrapedia/PDF discrep | L1: PDF/PW discrepancy
A2: 1 | C2: With title page. | D2: "Found in Capitol Films envelope dated 1980." Detailed list of typed letters. | E2: Oct-Nov 1980 | F2: 29512 | G2: 29593 | H2: 308 | I2: 310 | J2: 310 | K2: =I2-J2 -> 0 | L2: =J2-H2 -> 2
A3: 2 | B3: Sept. 1978 (ca.)--PW | E3: 28734 | F3: 28734 | G3: 28763 | H3: 90 | I3: 90 | J3: 90 | K3: =I3-J3 -> 0 | L3: =J3-H3 -> 0
A4: 3 | B4: Sept. 7 1978 (PW) | E4: 28734 | F4: 28734 | G4: 28763 | H4: 88 | I4: 88 | J4: 88 | K4: =I4-J4 -> 0 | L4: =J4-H4 -> 0
A5: 5 | C5: Missing 9-p. piece "A dream, from St. Sophia"- Prob. removed for privacy reasons, due to note "heavy analysis of impending break-up with Tessa") | D5: "letters 2/75-9/76" | E5: 1975-1976 | F5: 27452 | G5: 28033 | H5: 313 | I5: 312 | J5: 312 | K5: =I5-J5 -> 0 | L5: =J5-H5 -> -1
A6: 6 | E6: 1979-early (2) | F6: 28856 | G6: 28886 | H6: 72 | I6: 72 | J6: 72 | K6: =I6-J6 -> 0 | L6: =J6-H6 -> 0
A7: 8 | E7: 1979-early (1) | F7: 28856 | G7: 28886 | H7: 26 | I7: 26 | J7: 26 | K7: =I7-J7 -> 0 | L7: =J7-H7 -> 0
A8: 9 | E8: 1978-12 | F8: 28825 | G8: 28855 | H8: 76 | I8: 76 | J8: 76 | K8: =I8-J8 -> 0 | L8: =J8-H8 -> 0
A9: 10 | E9: 1979-early (3) | F9: 28887 | G9: 28914 | H9: 115 | I9: 115 | J9: 115 | K9: =I9-J9 -> 0 | L9: =J9-H9 -> 0
A10: 11 | E10: 1978-12 | F10: 28825 | G10: 28855 | H10: 86 | I10: 86 | J10: 86 | K10: =I10-J10 -> 0 | L10: =J10-H10 -> 0
A11: 12 | F11: ?? | G11: ?? | H11: 30 | I11: 30 | J11: 30 | K11: =I11-J11 -> 0 | L11: =J11-H11 -> 0
A12: 13 | C12: Expanded with new scans. | E12: 1979-early (4) | F12: 1979-01 | G12: 1979-04 | H12: 60 | I12: 60 | J12: 60 | K12: =I12-J12 -> 0 | L12: =J12-H12 -> 0
A13: 14 | E13: Mar-Apr 1978 | F13: 28550 | G13: 28610 | H13: 128 | I13: 130 | J13: 130 | K13: =I13-J13 -> 0 | L13: =J13-H13 -> 2
A14: 15 | E14: 28611 | F14: 28611 | G14: 28641 | H14: 146 | I14: 146 | J14: 146 | K14: =I14-J14 -> 0 | L14: =J14-H14 -> 0 | M14: pkd-folder-15
A15: 16 | E15: Jun-Jul 1978 | F15: 28642 | G15: 28701 | H15: 116 | I15: 116 | J15: 116 | K15: =I15-J15 -> 0 | L15: =J15-H15 -> 0
A16: 20 | C16: Expanded with new scans. | E16: 28764 | F16: 1978-10 | G16: 1978-10 | H16: 82 | I16: 82 | J16: 82 | K16: =I16-J16 -> 0 | L16: =J16-H16 -> 0
A17: 21 | C17: Expanded with new scans. | E17: Oct 18 1977 | F17: 10-18-19771 | G17: 10-18-19771 | H17: 142 | I17: 142 | J17: 142 | K17: =I17-J17 -> 0 | L17: =J17-H17 -> 0
A18: 22 | E18: Oct-Nov 1978 | F18: 28764 | G18: 28824 | H18: 118 | I18: 118 | J18: 118 | K18: =I18-J18 -> 0 | L18: =J18-H18 -> 0
A19: 24 | E19: 28126 | F19: 28126 | G19: 28156 | H19: 88 | I19: 88 | J19: 88 | K19: =I19-J19 -> 0 | L19: =J19-H19 -> 0
A20: 25 | E20: Jan-Feb 1977 | F20: 28127 | G20: 28184 | H20: 50 | I20: 50 | J20: 50 | K20: =I20-J20 -> 0 | L20: =J20-H20 -> 0
A21: 26 | E21: 28157 | F21: 28157 | G21: 28184 | H21: 81 | I21: 81 | J21: 81 | K21: =I21-J21 -> 0 | L21: =J21-H21 -> 0
A22: 27 | E22: 28185 | F22: 28185 | G22: 28215 | H22: 110 | I22: 111 | J22: 111 | K22: =I22-J22 -> 0 | L22: =J22-H22 -> 1 | M22: pkd-folder-27
A23: 28 | E23: 28522 | F23: 28522 | G23: 28549 | H23: 52 | I23: 52 | J23: 52 | K23: =I23-J23 -> 0 | L23: =J23-H23 -> 0 | M23: Some pages out of order?
A24: 29 | E24: 28550 | F24: 28550 | G24: 28579 | H24: 90 | I24: 90 | J24: 90 | K24: =I24-J24 -> 0 | L24: =J24-H24 -> 0
A25: 30 | E25: 1978 (early) | F25: 28491 | G25: 28640 | H25: 26 | I25: 26 | J25: 26 | K25: =I25-J25 -> 0 | L25: =J25-H25 -> 0
A26: 31 | E26: 28399 | F26: 28399 | G26: 28429 | H26: 83 | I26: 83 | J26: 83 | K26: =I26-J26 -> 0 | L26: =J26-H26 -> 0
A27: 32 | E27: Nov 19 1977 | F27: 28448 | G27: 28448 | H27: 11 | I27: 12 | J27: 11 | K27: =I27-J27 -> 1 | L27: =J27-H27 -> 0
A28: 33 | E28: 28338 | F28: 28338 | G28: 28368 | H28: 20 | I28: 20 | J28: 20 | K28: =I28-J28 -> 0 | L28: =J28-H28 -> 0
A29: 34 | E29: Jun-Jul 1977 | F29: 28277 | G29: 28306 | H29: 14 | I29: 14 | J29: 14 | K29: =I29-J29 -> 0 | L29: =J29-H29 -> 0
A30: 35 | E30: 28307 | F30: 28307 | G30: 28337 | H30: 12 | I30: 12 | J30: 12 | K30: =I30-J30 -> 0 | L30: =J30-H30 -> 0
A31: 36 | D31: PW gives 41 as the tally, but it seems that it should be 40. | E31: Aug-Sept 1977 | F31: 28338 | G31: 28369 | H31: 40 | I31: 40 | J31: 40 | K31: =I31-J31 -> 0 | L31: =J31-H31 -> 0
A32: 38 | E32: 28703 | F32: 28703 | G32: 28733 | H32: 97 | I32: 96 | J32: 96 | K32: =I32-J32 -> 0 | L32: =J32-H32 -> -1
A33: 39 | E33: 28915 | F33: 28915 | G33: 28945 | H33: 81 | I33: 81 | J33: 81 | K33: =I33-J33 -> 0 | L33: =J33-H33 -> 0
A34: 40 | F34: 28399 | G34: 28429 | H34: 32 | I34: 32 | J34: 32 | K34: =I34-J34 -> 0 | L34: =J34-H34 -> 0
A35: 44 | C35: Missing page is verso of one of the pages between 76 and 77. | E35: 1979 | F35: 28856 | G35: 29220 | H35: 197 | I35: 196 | J35: 196 | K35: =I35-J35 -> 0 | L35: =J35-H35 -> -1
A36: 45 | E36: 1979 | F36: 28856 | G36: 29220 | H36: 204 | I36: 204 | J36: 204 | K36: =I36-J36 -> 0 | L36: =J36-H36 -> 0
A37: 46 | C37: PW misses a duplicated number (416) but lists a typed page that is not present; net 1 page missing. | E37: 1979 | F37: 28856 | G37: 29220 | H37: 210 | I37: 209 | J37: 209 | K37: =I37-J37 -> 0 | L37: =J37-H37 -> -1
A38: 48 | E38: 1979 | F38: 28856 | G38: 29220 | H38: 206 | I38: 204 | J38: 204 | K38: =I38-J38 -> 0 | L38: =J38-H38 -> -2
A39: 49 | E39: 1980-01 | F39: 29221 | G39: 29251 | H39: 164 | I39: 164 | J39: 164 | K39: =I39-J39 -> 0 | L39: =J39-H39 -> 0
A40: 50 | E40: 28491 | F40: 28491 | G40: 28521 | H40: 152 | I40: 152 | J40: 152 | K40: =I40-J40 -> 0 | L40: =J40-H40 -> 0
...

Sheet Page sequences
A1: Folder | B1: Page # begin | C1: Page # end | D1: # of pages | E1: Date | F1: Date evidence | G1: Notes
A2: 1 | B2: Title page | D2: 1 | E2: 29557 | F2: Stated
A3: 1 | B3: 498 | C3: 543 | D3: 43 | E3: 29512 | G3: Some typed pages, possibly from another sequence. PP533-537 lacking.
A4: 1 | B4: 1 | C4: 4 | D4: 4 | E4: 29513 | F4: Stated | G4: Typed
A5: 1 | B5: 1 | C5: 10 | D5: 10 | E5: 29514 | F5: Stated | G5: Typed
A6: 1 | B6: 1 | C6: 8 | D6: 8 | E6: 29515 | F6: Stated | G6: Typed
A7: 1 | B7: 641 | C7: 645 | D7: 5 | E7: 29515 | F7: Stated | H7: (after 10/20)
A8: 1 | B8: 9 | C8: 9 | D8: 1 | E8: 29515 | G8: Typed
A9: 1 | B9: 1 | C9: 4 | D9: 4 | E9: 29516 | F9: Stated | G9: Typed | H9: Continues from last page of 10-21-80 typed
A10: 1 | B10: 1 | C10: 4 | D10: 4 | E10: 29517 | F10: Stated | G10: Typed
A11: 1 | B11: 1 | C11: [7] | D11: 7 | E11: 29518 | F11: Stated | G11: Typed | H11: Briefer later dates on last couple pages
A12: 1 | B12: 1 | C12: 5 | D12: 5 | E12: 29519 | F12: Stated | G12: Typed | H12: Continues from last page of 10-24-80
A13: 1 | B13: 1 | C13: 1 | D13: 1 | E13: 29520 | F13: Stated | G13: Typed
A14: 1 | B14: 1 | C14: 2 | D14: 2 | E14: 29526 | F14: Stated | G14: Typed
A15: 1 | B15: 1 | C15: 2 | D15: 2 | E15: 29527 | F15: Stated | G15: Typed
A16: 1 | B16: 595 | C16: 634 | D16: 30 | E16: 29528 | F16: Stated | H16: 609-10 , 623-29 lacking
A17: 1 | B17: 656 | C17: 660 | D17: 4 | E17: 29515 | F17: inferred
A18: 1 | B18: 648 | C18: 655 | D18: 8 | E18: 29515 | F18: inferred | H18: "III"
A19: 1 | B19: 661 | C19: 663 | D19: 3 | E19: 29515 | F19: inferred | H19: "IV"
A20: 1 | B20: 685 | C20: 687 | D20: 3 | E20: 29515 | F20: inferred | H20: "V"
A21: 1 | B21: 1 | C21: 6 | D21: 6 | E21: 29532 | F21: Stated | G21: Typed | H21: "VI"
A22: 1 | B22: Addendum 1 | C22: addendum 2 | D22: 2 | E22: 29532 | F22: Stated | G22: Typed
A23: 1 | B23: 1 | C23: 5 | D23: 5 | E23: 29542 | H23: "XV". The 11-17-80 Theophany
A24: 1 | B24: 855 | C24: 858 | D24: 4 | E24: 29556 | F24: inferred | H24: Concludes: "End." Footnote written later than 12-10-1980.
A25: 1 | B25: 1 | C25: 4 | D25: 4 | E25: 29556 | F25: inferred | H25: Footnote to "end" on p.858
A26: 1 | B26: 1 | C26: 2 | D26: 2 | E26: 29549 | F26: stated | G26: typed
A27: 1 | B27: 1 | C27: 7 | D27: 7 | E27: 29593 | F27: stated | G27: Typed
A28: 1 | B28: 688 | C28: 693 | D28: 6 | E28: 29515 | F28: inferred | H28: "VII"
A29: 1 | B29: 707 | C29: 728 | D29: 22 | E29: 29516 | F29: inferred | H29: "VIII". Some page numbers apparently repeated at the beginning of the sequence.
A30: 1 | B30: 743 | C30: 820 | D30: 72 | E30: 29522 | F30: inferred | H30: "IX"; "XI" beginning at p.772; "XII" at 791; "XIII" at 804. Some page numbers apparently skipped in sequence, but text appears uninterrupted.
A31: 1 | B31: nn[1] | C31: nn[5] | D31: 5 | E31: 29541 | F31: stated | G31: typed | H31: "XIV"
A32: 1 | B32: 825 | C32: 829 | D32: 4 | E32: 29541 | F32: inferred
A33: 1 | B33: 835 | C33: 846 | D33: 11 | E33: 29541 | F33: inferred
A34: 1 | B34: 1 | C34: 7 | D34: 7 | E34: 29543 | F34: inferred | H34: "XVII"
A35: 1 | B35: 21 | C35: 27 | D35: 7 | E35: 29544 | F35: inferred
A36: 1 | B36: 23 | C36: 24 | D36: 2 | E36: 29544 | F36: inferred | H36: "XVIII". Overlaps with pagination from 21-27, is this de facto 28-29?
A37: 2 | B37: 1 | C37: 89 | D37: 90 | E37: 28734 | F37: PW | H37: One page number repeated (bu PKD)by mistake.
A38: 3 | B38: 1 | C38: 94 | D38: 88 | E38: 28734 | F38: PW | H38: 41-46 lacking.
A39: 5 | B39: 1 | C39: 11 | D39: 11 | E39: 27452 | F39: Stated | G39: Typed w/handwritten diagram page | H39: Letter to Claudia. Assuming diagram (pdf p11) is the missing p4
A40: 5 | B40: 1 | C40: 1 | D40: 1 | E40: 27455 | F40: Stated | G40: Typed letter to Phylils Boucher.
...

Sheet Folder ordering
A1: Earliest date | B1: latest date | C1: Folder number | D1: Proposed new ordering number
A2: ='Folder pagecounts and compariso'!F70 -> 1 | B2: ='Folder pagecounts and compariso'!G70 -> 2 | C2: ='Folder pagecounts and compariso'!A70 -> 51 | D2: 0 | E2: Missing from scans. PW notes not part of Exegesis.
A3: ='Folder pagecounts and compariso'!F59 -> 27061 | B3: ='Folder pagecounts and compariso'!G59 -> 27759 | C3: ='Folder pagecounts and compariso'!A59 -> 4 | D3: 1 | E3: Missing from scans.
A4: ='Folder pagecounts and compariso'!F5 -> 27452 | B4: ='Folder pagecounts and compariso'!G5 -> 28033 | C4: ='Folder pagecounts and compariso'!A5 -> 5 | D4: 2
A5: ='Folder pagecounts and compariso'!F92 -> 27760 | B5: ='Folder pagecounts and compariso'!G92 -> 28490 | C5: ='Folder pagecounts and compariso'!A92 -> 86 | D5: 3 | E5: Missing from scans.
A6: ='Folder pagecounts and compariso'!F64 -> 28065 | B6: ='Folder pagecounts and compariso'!G64 -> 28125 | C6: ='Folder pagecounts and compariso'!A64 -> 23 | D6: 4 | E6: Missing from scans.
A7: ='Folder pagecounts and compariso'!F19 -> 28126 | B7: ='Folder pagecounts and compariso'!G19 -> 28156 | C7: ='Folder pagecounts and compariso'!A19 -> 24 | D7: 5
A8: ='Folder pagecounts and compariso'!F20 -> 28127 | B8: ='Folder pagecounts and compariso'!G20 -> 28184 | C8: ='Folder pagecounts and compariso'!A20 -> 25 | D8: 6
A9: ='Folder pagecounts and compariso'!F21 -> 28157 | B9: ='Folder pagecounts and compariso'!G21 -> 28184 | C9: ='Folder pagecounts and compariso'!A21 -> 26 | D9: 7
A10: ='Folder pagecounts and compariso'!F22 -> 28185 | B10: ='Folder pagecounts and compariso'!G22 -> 28215 | C10: ='Folder pagecounts and compariso'!A22 -> 27 | D10: 8
A11: ='Folder pagecounts and compariso'!F29 -> 28277 | B11: ='Folder pagecounts and compariso'!G29 -> 28306 | C11: ='Folder pagecounts and compariso'!A29 -> 34 | D11: 9
A12: ='Folder pagecounts and compariso'!F30 -> 28307 | B12: ='Folder pagecounts and compariso'!G30 -> 28337 | C12: ='Folder pagecounts and compariso'!A30 -> 35 | D12: 10
A13: ='Folder pagecounts and compariso'!F28 -> 28338 | B13: ='Folder pagecounts and compariso'!G28 -> 28368 | C13: ='Folder pagecounts and compariso'!A28 -> 33 | D13: 11
A14: ='Folder pagecounts and compariso'!F31 -> 28338 | B14: ='Folder pagecounts and compariso'!G31 -> 28369 | C14: ='Folder pagecounts and compariso'!A31 -> 36 | D14: 12
A15: ='Folder pagecounts and compariso'!F26 -> 28399 | B15: ='Folder pagecounts and compariso'!G26 -> 28429 | C15: ='Folder pagecounts and compariso'!A26 -> 31 | D15: 13
A16: ='Folder pagecounts and compariso'!F34 -> 28399 | B16: ='Folder pagecounts and compariso'!G34 -> 28429 | C16: ='Folder pagecounts and compariso'!A34 -> 40 | D16: 14
A17: ='Folder pagecounts and compariso'!F27 -> 28448 | B17: ='Folder pagecounts and compariso'!G27 -> 28448 | C17: ='Folder pagecounts and compariso'!A27 -> 32 | D17: 15
A18: ='Folder pagecounts and compariso'!F25 -> 28491 | B18: ='Folder pagecounts and compariso'!G25 -> 28640 | C18: ='Folder pagecounts and compariso'!A25 -> 30 | D18: 16
A19: ='Folder pagecounts and compariso'!F40 -> 28491 | B19: ='Folder pagecounts and compariso'!G40 -> 28521 | C19: ='Folder pagecounts and compariso'!A40 -> 50 | D19: 17
A20: ='Folder pagecounts and compariso'!F46 -> 28513 | B20: ='Folder pagecounts and compariso'!G46 -> 28513 | C20: ='Folder pagecounts and compariso'!A46 -> 58 | D20: 18
A21: ='Folder pagecounts and compariso'!F23 -> 28522 | B21: ='Folder pagecounts and compariso'!G23 -> 28549 | C21: ='Folder pagecounts and compariso'!A23 -> 28 | D21: 19
A22: ='Folder pagecounts and compariso'!F13 -> 28550 | B22: ='Folder pagecounts and compariso'!G13 -> 28610 | C22: ='Folder pagecounts and compariso'!A13 -> 14 | D22: 20
A23: ='Folder pagecounts and compariso'!F24 -> 28550 | B23: ='Folder pagecounts and compariso'!G24 -> 28579 | C23: ='Folder pagecounts and compariso'!A24 -> 29 | D23: 21
A24: ='Folder pagecounts and compariso'!F61 -> 28581 | B24: ='Folder pagecounts and compariso'!G61 -> 28671 | C24: ='Folder pagecounts and compariso'!A61 -> 17 | D24: 22 | E24: Missing from scans.
A25: ='Folder pagecounts and compariso'!F71 -> 28581 | B25: ='Folder pagecounts and compariso'!G71 -> 28610 | C25: ='Folder pagecounts and compariso'!A71 -> 52 | D25: 23 | E25: Missing from scans.
A26: ='Folder pagecounts and compariso'!F14 -> 28611 | B26: ='Folder pagecounts and compariso'!G14 -> 28641 | C26: ='Folder pagecounts and compariso'!A14 -> 15 | D26: 24
A27: ='Folder pagecounts and compariso'!F15 -> 28642 | B27: ='Folder pagecounts and compariso'!G15 -> 28701 | C27: ='Folder pagecounts and compariso'!A15 -> 16 | D27: 25
A28: ='Folder pagecounts and compariso'!F32 -> 28703 | B28: ='Folder pagecounts and compariso'!G32 -> 28733 | C28: ='Folder pagecounts and compariso'!A32 -> 38 | D28: 26
A29: ='Folder pagecounts and compariso'!F62 -> 28703 | B29: ='Folder pagecounts and compariso'!G62 -> 28733 | C29: ='Folder pagecounts and compariso'!A62 -> 18 | D29: 27 | E29: Missing from scans.
A30: ='Folder pagecounts and compariso'!F3 -> 28734 | B30: ='Folder pagecounts and compariso'!G3 -> 28763 | C30: ='Folder pagecounts and compariso'!A3 -> 2 | D30: 28
A31: ='Folder pagecounts and compariso'!F4 -> 28734 | B31: ='Folder pagecounts and compariso'!G4 -> 28763 | C31: ='Folder pagecounts and compariso'!A4 -> 3 | D31: 29
A32: ='Folder pagecounts and compariso'!F63 -> 28734 | B32: ='Folder pagecounts and compariso'!G63 -> 28794 | C32: ='Folder pagecounts and compariso'!A63 -> 19 | D32: 30 | E32: Missing from scans.
A33: ='Folder pagecounts and compariso'!F18 -> 28764 | B33: ='Folder pagecounts and compariso'!G18 -> 28824 | C33: ='Folder pagecounts and compariso'!A18 -> 22 | D33: 31
A34: ='Folder pagecounts and compariso'!F16 -> 1978-10 | B34: ='Folder pagecounts and compariso'!G16 -> 1978-10 | C34: ='Folder pagecounts and compariso'!A16 -> 20 | D34: 32
A35: ='Folder pagecounts and compariso'!F17 -> 10-18-19771 | B35: ='Folder pagecounts and compariso'!G17 -> 10-18-19771 | C35: ='Folder pagecounts and compariso'!A17 -> 21 | D35: 33
A36: ='Folder pagecounts and compariso'!F8 -> 28825 | B36: ='Folder pagecounts and compariso'!G8 -> 28855 | C36: ='Folder pagecounts and compariso'!A8 -> 9 | D36: 34
A37: ='Folder pagecounts and compariso'!F10 -> 28825 | B37: ='Folder pagecounts and compariso'!G10 -> 28855 | C37: ='Folder pagecounts and compariso'!A10 -> 11 | D37: 35
A38: ='Folder pagecounts and compariso'!F6 -> 28856 | B38: ='Folder pagecounts and compariso'!G6 -> 28886 | C38: ='Folder pagecounts and compariso'!A6 -> 6 | D38: 36
A39: ='Folder pagecounts and compariso'!F7 -> 28856 | B39: ='Folder pagecounts and compariso'!G7 -> 28886 | C39: ='Folder pagecounts and compariso'!A7 -> 8 | D39: 37
A40: ='Folder pagecounts and compariso'!F12 -> 1979-01 | B40: ='Folder pagecounts and compariso'!G12 -> 1979-04 | C40: ='Folder pagecounts and compariso'!A12 -> 13 | D40: 38
...

Sheet Sutin rundown
A1: Chapter | B1: Entry | C1: Sentence-open | D1: Sentence-close | E1: Sutin date | F1: Sutin page range | G1: Zebrapedia folder | H1: Zebpraedia start page
A2: 1 | B2: 1 | C2: The best psychiatrist I ever saw | D2: Out of memory. | E2: 27211 | F2: 1-20. | G2: 4 | H2: 42
A3: 1 | B3: 2 | C3: I awoke abruptly to find | D3: The summertime to greet | E3: 1975 | F3: 20-21. | G3: 5 | H3: 65
A4: 1 | B4: 3 | C4: One could assume, I guess, that the divine seed | D4: the progeny: Helen of Troy | E4: 1975 | F4: 21-23. | G4: 5 | H4: 71
A5: 1 | B5: 4 | C5: Every time in my life that I've heard the spirit | D5: Next step upward in human evolution?) Maybe so. | E5: 1975 | F5: 23-24. | G5: 5 | H5: 132
A6: 1 | B6: 5 | C6: Last night (June 2nd) I had a blissful truly | D6: a long way to go, yet | E6: 27548 | F6: 24-31. | G6: 5 | H6: 172
A7: 1 | B7: 6 | C7: Mark 4:11 says that the parables were intended | D7: Heraclitus says the Logos can be heard. My goodness. | E7: 1975 | F7: 31-32 | G7: 5 | H7: 231
A8: 1 | B8: 7 | C8: I am thinking back. Sitting with my eyes shut | D8: "We shall be like him" 1 JN 3:2 | E8: 1977 | F8: 32-34. | G8: 50 | H8: 16
A9: 1 | B9: 8 | C9: Pain is the good which most effectively | D9: and painful it is always good | E9: 1978 | F9: 34-35 | G9: 11 | H9: 31
A10: 1 | B10: 9 | C10: Oh God, I am so weary of this lonely world | D10: Klingsor & his castle of iron. Libera me, Domine! | E10: 28672 | F10: 35 | G10: 16 | H10: 9
A11: 1 | B11: 10 | C11: Yes, it was a mercy to me | D11: Or it all falls. I think it stands | E11: 1978 | F11: 35-38. | G11: 18 | H11: 25
A12: 1 | B12: 11 | C12: Consider what the Ai voice has said recently | D12: I have every reason to believe he picked me | E12: 1978 | F12: 38-39. | G12: 20 | H12: 75
A13: 1 | B13: 12 | C13: Well, thinking this, about how Zoroastrianism | D13: free way of being, & progressively more so | E13: 1978 | F13: 39-41. | G13: 39 | H13: 37
A14: 1 | B14: 13 | C14: Dream: I am Jerry Lewis | D14: The dying leader and his loyal troops | E14: 1979 | F14: 41 | G14: 42 | H14: 39
A15: 1 | B15: 14 | C15: What does it mean -- how can it be | D15: Und wo? & wie? Die zeit ist heir! | E15: 1979 | F15: 41-42 | G15: 41 | H15: 52
A16: 1 | B16: 15 | C16: How can I ascertain my role? | D16: God by ritual identification. Christ, obviously | E16: 1979 | F16: 42-43 | G16: 45 | H16: 203
A17: 1 | B17: 16 | C17: All I really know is that there is another mind | D17: a macro-mind that can cause to be whatever he wishes | E17: 1979 | F17: 43-44 | J17: Unlocated
A18: 1 | B18: 17 | C18: It really does not make sense to say | D18: I saw with the ajna eye | E18: 1979 | F18: 44-45. | G18: 49 | H18: 163
A19: 1 | B19: 18 | C19: God manifested himself to me as the infinite void | D19: Play again. I am waiting. | E19: 29542 | F19: 45-51. | G19: 1 | H19: 156
A20: 1 | B20: 19 | C20: God said that I couldn't know with certainty | D20: not conclusive but they are compelling | E20: 29549 | F20: 51-53 | G20: 1 | H20: 169
A21: 1 | B21: 20 | C21: So satan served me up a sophisticated world | D21: But someday it will end. END | E21: 29557 | F21: 53-57 | G21: 1 | H21: 161
A22: 1 | B22: 21 | C22: Footnote. My flight expressed | D22: first heard the Ai voice. 35 years! | E22: 29565 | F22: 59-62. | G22: 1 | H22: 165
A23: 2 | B23: 1 | C23: In Ubik the forward moving force | D23: It looked out and saw itself | E23: 1974 | F23: 63-67 | G23: 4 | H23: 1
A24: 2 | B24: 2 | C24: My whole God is identified with a vitalizing | D24: Orphic: rebirth. Rejuvenation (eternal life) | E24: 1975 | F24: 67-70 | G24: 5 | H24: 77
A25: 2 | B25: 3 | C25: A searingly important realization | D25: Which I knew nothing about, when I wrote them | E25: 1977 | F25: 70-71 | G25: 50 | H25: 99
A26: 2 | B26: 4 | C26: If there is, as the Gnostics believe, a blind | D26: the BIP is dead & rigid & mnotonous & simple | E26: 1978 | F26: 71-72 | G26: 9 | H26: 25
A27: 2 | B27: 5 | C27: Definition of what I experienced in 3-74: ZEBRA | D27: from info by Valis' perfect memory | E27: 1978 | F27: 72 | J27: Unlocated
A28: 2 | B28: 6 | C28: Here is a modified, more precise model | D28: with them. 2 points of overlap. | E28: 1978 | F28: 73-74 | G28: 14 | H28: 31
A29: 2 | B29: 7 | C29: Stigmata portrays the arrogant one | D29: the heroic deed(s) done, the PTG). | E29: 1978 | F29: 75-76 | G29: 14 | H29: 45
A30: 2 | B30: 8 | C30: By the very nature it is deus absconditus | D30: I did know-- I did understand | E30: 1978 | F30: 76-77 | G30: 24 | H30: 88 | I30: Ecce Deum drawing
A31: 2 | B31: 9 | C31: K. W. has noted a resemblance between | D31: Burroughs' novel is relaetd to Ubik and Stigmata via the 3-74 experience | E31: 1978 | F31: 77-78 | G31: 29 | H31: 10
A32: 2 | B32: 10 | C32: The criminal virus controls by occluding | D32: i.e., immortality is possible | E32: 1978 | F32: 79 | G32: 28 | H32: 10 | I32: Criminal Virus drawings
A33: 2 | B33: 11 | C33: Zebra is the supreme deity & savior-messenger | D33: trashy form, like in Ubik | E33: 1978 | F33: 79 | G33: 21 | H33: 43
A34: 2 | B34: 12 | C34: Something ("Y") is recognized | D34: offshoot I passed over into paradise | E34: 1978 | F34: 79-80 | G34: 22 | H34: 63
A35: 2 | B35: 13 | C35: It can be said that the yin part "hatched" | D35: latter is alien to the N.T. God | E35: 1978 | F35: 80-81 | G35: 38 | H35: 64
A36: 2 | B36: 14 | C36: My life has divided this way | D36: Thus I returned to God & entered the Kingdom | E36: 1978 | F36: 81 | G36: 21 | H36: 46
A37: 2 | B37: 15 | C37: In schizophrenia the synchronization of inner | D37: received, since it is God himself | E37: 1978 | F37: 81-82 | G37: 21 | H37: 137
A38: 2 | B38: 16 | C38: Tears showed I had vestigal memories before | D38: Can the Black Iron world come back? | E38: 1978 | F38: 82-83 | G38: 24 | H38: 47
A39: 2 | B39: 17 | C39: The creator can afford to descend | D39: patron God of small trapped animals | E39: 1978 | F39: 83-85 | G39: 21 | H39: 2
A40: 2 | B40: 18 | C40: Kerygma understood as of October 18 1978 | D40: Original early Christian disciples are still alive | E40: 28781 | F40: 85-87 | G40: 21 | H40: 1
...

Sheet Jackson-Lethem rundown
A1: Sequence | B1: Identified folder and page | C1: Opening line | D1: Closing line | E1: Note | F1: Pages | G1: Sutin or other correlation
A2: 1 | B2: 4:1 | C2: In Ubik the forward moving | D2: looked out and saw itself
A3: 2 | B3: 4:6 | C3: Dear Peter, […] in regards to the tone | D3: your opinion uniquely | E3: Letter to Peter Fitting 6/28/74 | G3: Selected Letters 6/28/74 (I trust)
A4: 3 | B4: 4:13 | C4: Dear Claudia, Since I last wrote you (sending | D4: you have nothing planned? | E4: Letter to Claudia Bush 7/5/74 | G4: Selected Letters 7/5/74 (I trust)
A5: 4 | B5: 4:16 | C5: Dear Claudia, […] Inasmuch as Iv'e delighted you | D5: It must be back for a reason | E5: Letter to Claudia Bush 7/13/74 | G5: Selected Letters 7/13/74 (I trust)
A6: 5 | B6: 4:34 | C6: Dear Claudia, Herewith you will find | E6: Letter to Claudia Bush 7/16/74 | G6: Selected Letters 7/16/74 (I trust)
A7: 6 | B7: 4:34 [enclosure] | C7: July 8, 1974 First day of the constitutional crisis | G7: Sutin 233-237
A8: 7 | B8: 4:41 | C8: The best psychiatrist I ever saw | D8: Out of memory | G8: Sutin pp1-20
A9: 8 | B9: 4:? | C9: Dear Claudia, I think I've solved what's been in my head | D9: I sure have odd nights. | E9: Letter to Claudia Bush 7/22/74 | G9: Selected Letters 7/22/74 (I trust)
A10: 9 | B10: 4:? | C10: Dear Claudia, I will xerox the Philip Purser | D10: Freudian slip; sorry. Write any time. | E10: Letter to Claudia Bush 7/24/74 | G10: Selected Letters 7/24/74 (I trust)
A11: 10 | B11: 4:? | C11: Dear Claudia, Claudia! Another letter! | D11: Demeter for instance | E11: Letter to Claudia Bush 7/24/74 | G11: Selected Letters 7/24/74 (I trust)
A12: 11 | B12: 4:? | C12: The Other is not any one thing | D12: This is the Logos perhaps
A13: 12 | B13: 4:? | C13: Dear Ursula, I just sent you a big manila envelope | D13: always clearly at the future | E13: Letter to Ursula Le Guin 9/23/74 | G13: Selected Letters 9/23/74 (I trust)
A14: 13 | B14: 4:? | C14: Dear Claudia, The other day I lay down | D14: all move into action | E14: Letter to Claudia Bush 9/26/74 | G14: Selected Letters 9/26/74 (I trust)
A15: 14 | B15: 4:? | C15: Dear Claudia, Can I rattle on some more | D15: and he'll have had it | E15: Letter to Claudia Bush 11/29/74 | G15: Selected Letters 11/29/74 (I trust)
A16: 15 | B16: 4:? | C16: Dear Claudia, I just wrote Diane Pike | D16: results are outta sight | E16: Letter to Claudia Bush 11/30/74 | G16: Selected Letters 11/30/74 (I trust)
A17: 16 | B17: 4:? | C17: A human being is a material system | D17: Or however.
A18: 17 | B18: 4:? | C18: The right hemisphere is the seat | D18: outer ones together
A19: 18 | B19: 4:? | C19: Jesus said to the disciples | D19: me-not me will be transcended | E19: Enclosed with Jan. 27, 1975 letter to Williams | G19: Sutin 250-251
A20: 19 | B20: 4:? | C20: Dear Malcolm, […] One thing I've meant to write you | D20: Thank you for your article on Tears | E20: Letter to Malcolm [Hulke?] 1/29/1975 | G20: Selected Letters 1/29/75 (I trust)
A21: 20 | B21: 4:? | C21: Dear Malcolm, Would you object if I completed | D21: I hope you're not displeased | E21: Letter to Malcolm [Hulke?] 1/31/1975 | G21: Selected Letters 1/31/75 (I trust)
A22: 21 | B22: 4:? | C22: Dear Claudia, It seems to me that one of the most | D22: that he may acquire it | E22: Letter to Claudia Bush 2/13/75 | G22: Selected Letters 2/13/75 (I trust)
B23: 4:? | C23: The forms (categories such as "transportation") | D23: the latter Rome is what I saw
